<?xml version="1.0"?>

<robot xmlns:xacro="http://www.ros.org/wiki/xacro">

  <xacro:property name="pi" value="3.1415926535897931" />
  <xacro:property name="camera_offset_len" value="0.1" />
  <xacro:property name="camera_offset_ver" value="0.0" />
  <!-- +- 35 degrees -->
  <xacro:property name="pan_range" value="0.6108652381980153" />
  <xacro:property name="pan_vel" value="2.0" />
  <!-- +- 80 degrees -->
  <xacro:property name="tilt_range" value="1.396263402" />
  <xacro:property name="tilt_vel" value="5.0" />
  <xacro:property name="joint_effort" value="50" />


  <!-- Main quadrotor link -->
  <xacro:macro name="bebop_base_macro">
    <link name="base_link">
      <inertial>
        <mass value="0.399" />
        <origin xyz="0 0 0" />
        <inertia ixx="0.01152" ixy="0.0" ixz="0.0" iyy="0.01152" iyz="0.0" izz="0.0218" />
        <!-- Inertia from hector quadrotor, sorry! -->
      </inertial>

      <visual>
        <origin xyz="0 0 0" rpy="0 0 0" />
        <geometry>
          <mesh filename="package://bebop_gazebo/meshes/bebop_model.stl"/>
        </geometry>
        <material name="blue">
          <color rgba="0 0.4 0.6 1"/>
        </material>
      </visual>

      <collision>
        <origin xyz="0 0 0" rpy="0 0 0" />
        <geometry>
          <mesh filename="package://bebop_gazebo/meshes/bebop_model.stl"/>
        </geometry>
      </collision>
    </link>
    <gazebo reference="base_link">  <!--Bebop painting-->
      <material>Gazebo/Blue</material>
    </gazebo>

    <link name="camera_base_link"></link>
    <link name="camera_pan_link"></link>
    <link name="camera_tilt_link"></link>
    <link name="camera_optical"></link>

    <joint name="base_link_joint" type="fixed">
      <origin xyz="${camera_offset_len} 0 ${camera_offset_ver}" rpy="0 0 0" />    <!--Camera rotated-->
      <parent link="base_link"/>
      <child link="camera_base_link" />
    </joint>

    <joint name="camera_pan_joint" type="revolute">
      <origin xyz="0 0 0" rpy="0 0 0" />
      <parent link="camera_base_link" />
      <child link="camera_pan_link" />
      <axis xyz="0 0 1" />
      <limit lower="${-pan_range}" upper="${pan_range}"
        effort="${joint_effort}" velocity="${pan_vel}" />
    </joint>

    <joint name="camera_tilt_joint" type="revolute">
      <origin xyz="0 0 0" rpy="0 0 0" />
      <parent link="camera_pan_link" />
      <child link="camera_tilt_link" />
      <axis xyz="0 1 0" />
      <limit lower="${-tilt_range}" upper="${tilt_range}"
        effort="${joint_effort}" velocity="${tilt_vel}" />
    </joint>

    <joint name="camera_optical_joint" type="fixed">
      <origin xyz="0 0 0" rpy="${-pi/2} 0 ${-pi/2}" />
      <parent link="camera_tilt_link" />
      <child link="camera_optical" />
    </joint>

<!-- ................................................................ -->
    <!-- Added Raspberry camera -->
    <link name="raspberry_camera_link">
      <visual>
        <geometry>
          <box size = "0.004 0.025 0.024" />          <!-- Real dimensions of Raspberry Camera v2.1 -->
        </geometry>
      </visual>

      <inertial>
        <mass value="0.003" />
        <inertia ixx="0.0001" ixy="0.0" ixz="0.0" iyy="0.0001" iyz="0.0" izz="0.0001"/>
      </inertial>
    </link>
    <gazebo reference="raspberry_camera_link">
      <material>Gazebo/Red</material>
    </gazebo>

    <joint name="raspberry_camera_joint" type="fixed">
      <origin xyz="0.055 0 -0.002" rpy="0 ${pi/2} 0" />
      <parent link="base_link" />
      <child link="raspberry_camera_link" />
      <!-- <axis xyz="1 0 0" /> -->
      <!-- <limit lower="0" upper="1"
        effort="0" velocity="0" /> -->
    </joint>

    <joint name="raspberry_optical_joint" type="fixed">
      <origin xyz="0 0 0" rpy="${-pi/2} 0 ${-pi/2}"/>
      <parent link="raspberry_camera_link" />
      <child link="raspberry_optical" />
    </joint>

    <link name="raspberry_optical"></link>

<!-- ................................................................ -->
  </xacro:macro>
</robot>
